Workbook

Sheet README
A1: Nama | B1: Muchammad Wildan Alkautsar
A2: Penjelasan Pembersihan Data | B2: - Nilai null pada tanggal_pengiriman diatasi dengan membuat kolom clean_tanggal_pengiriman dan mengisinya menggunakan tanggal_pemesanan + 3 hari berdasarkan asumsi waktu pengiriman standar. - Nilai null pada kolom kota diisi pada kolom clean_kota menggunakan fungsi XLOOKUP dengan referensi dari subsheet reference_province_to_city.- - Nilai null pada kolom kode_pos diatasi dengan membuat kolom clean_kode_pos menggunakan fungsi XLOOKUP dengan referensi dari subsheet reference_postal_code. - Duplicate values dihapus menggunakan fitur Data → Data cleanup → Remove duplicates, sehingga jumlah data berkurang dari 10.493 menjadi 10.076 baris.
A6: CONTOH
A8: Nama | B8: Yohan
A9: Penjelasan Pembersihan Data | B9: - Nilai null pada tanggal_pengiriman diisi dengan nilai yang sama pada tanggal pemesanan. Hal ini ditujukan dengan asumsi barang dikirim di waktu yang sama dan secara bisnis masih masuk akal. - xxx

Sheet sources
A1: row_id | B1: order_id | C1: tanggal_pemesanan | D1: tanggal_pengiriman | E1: clean_tanggal_pengiriman | F1: metode_pengiriman | G1: customer_id | H1: nama_pelanggan | I1: segmen | J1: negara | K1: kota | L1: clean_kota | M1: provinsi | N1: kode_pos | O1: clean_kode_pos | P1: wilayah | Q1: product_id | R1: kategori | S1: sub_kategori | T1: nama_produk | U1: penjualan | V1: kuantitas | W1: diskon | X1: keuntungan
A2: 7981 | B2: IDN-2014-103800 | C2: 41642 | D2: 41646 | E2: =IF(D2="", C2+3, D2) -> 41646 | F2: Standard Class | G2: YD-6879 | H2: Yulia Damanik | I2: Consumer | J2: Indonesia | K2: Makassar | L2: {=_xlfn.XLOOKUP(M2,reference_province_to_city!$A$2:$A$11,reference_province_to_city!$B$2:$B$11)} -> Makassar | M2: Sulawesi Selatan | N2: 90111 | O2: {=_xlfn.XLOOKUP(M2,reference_postal_code!$B$2:$B$11,reference_postal_code!$A$2:$A$11)} -> 90111 | P2: South | Q2: OFF-PA-10000174 | R2: Office Supplies | S2: Paper | T2: Kertas Foto 5240 | U2: 246720 | V2: 2 | W2: 0.2 | X2: 83268
A3: 740 | B3: IDN-2014-112326 | C3: 41643 | D3: 41647 | E3: =IF(D3="", C3+3, D3) -> 41647 | F3: Standard Class | G3: GS-1390 | H3: Genta Saefullah | I3: Home Office | J3: Indonesia | K3: Yogyakarta | L3: {=_xlfn.XLOOKUP(M3,reference_province_to_city!$A$2:$A$11,reference_province_to_city!$B$2:$B$11)} -> Yogyakarta | M3: DI Yogyakarta | N3: 55111 | O3: {=_xlfn.XLOOKUP(M3,reference_postal_code!$B$2:$B$11,reference_postal_code!$A$2:$A$11)} -> 55111 | P3: Central | Q3: OFF-LA-10003223 | R3: Office Supplies | S3: Labels | T3: Label Harga 3161 | U3: 176760 | V3: 3 | W3: 0.2 | X3: 64075
A4: 742 | B4: IDN-2014-112326 | C4: 41643 | D4: 41647 | E4: =IF(D4="", C4+3, D4) -> 41647 | F4: Standard Class | G4: GS-1390 | H4: Genta Saefullah | I4: Home Office | J4: Indonesia | K4: Yogyakarta | L4: {=_xlfn.XLOOKUP(M4,reference_province_to_city!$A$2:$A$11,reference_province_to_city!$B$2:$B$11)} -> Yogyakarta | M4: DI Yogyakarta | N4: 55111 | O4: {=_xlfn.XLOOKUP(M4,reference_postal_code!$B$2:$B$11,reference_postal_code!$A$2:$A$11)} -> 55111 | P4: Central | Q4: OFF-BI-10004094 | R4: Office Supplies | S4: Binders | T4: Binder Plastik A4 1084 | U4: 53100 | V4: 2 | W4: 0.8 | X4: -82305
A5: 741 | B5: IDN-2014-112326 | C5: 41643 | D5: 41647 | E5: =IF(D5="", C5+3, D5) -> 41647 | F5: Standard Class | G5: GS-1390 | H5: Genta Saefullah | I5: Home Office | J5: Indonesia | K5: Yogyakarta | L5: {=_xlfn.XLOOKUP(M5,reference_province_to_city!$A$2:$A$11,reference_province_to_city!$B$2:$B$11)} -> Yogyakarta | M5: DI Yogyakarta | N5: 55111 | O5: {=_xlfn.XLOOKUP(M5,reference_postal_code!$B$2:$B$11,reference_postal_code!$A$2:$A$11)} -> 55111 | P5: Central | Q5: OFF-ST-10002743 | R5: Office Supplies | S5: Storage | T5: Lemari Arsip 4745 | U5: 4091040 | V5: 3 | W5: 0.2 | X5: -971622
A6: 1760 | B6: IDN-2014-141817 | C6: 41644 | D6: 41651 | E6: =IF(D6="", C6+3, D6) -> 41651 | F6: Standard Class | G6: KF-4096 | H6: Kariman Firgantoro | I6: Consumer | J6: Indonesia | K6: Palembang | L6: {=_xlfn.XLOOKUP(M6,reference_province_to_city!$A$2:$A$11,reference_province_to_city!$B$2:$B$11)} -> Palembang | M6: Sumatera Selatan | N6: 30111 | O6: {=_xlfn.XLOOKUP(M6,reference_postal_code!$B$2:$B$11,reference_postal_code!$A$2:$A$11)} -> 30111 | P6: Central | Q6: OFF-AR-10003478 | R6: Office Supplies | S6: Art | T6: Lukisan Cat Air 9781 | U6: 293040 | V6: 3 | W6: 0.2 | X6: 73260
A7: 7480 | B7: IDN-2014-167199 | C7: 41645 | D7: 41649 | E7: =IF(D7="", C7+3, D7) -> 41649 | F7: Standard Class | G7: KH-9486 | H7: Kairav Hutagalung | I7: Home Office | J7: Indonesia | K7: DENPASAR | L7: {=_xlfn.XLOOKUP(M7,reference_province_to_city!$A$2:$A$11,reference_province_to_city!$B$2:$B$11)} -> Denpasar | M7: Bali | N7: 80231 | O7: {=_xlfn.XLOOKUP(M7,reference_postal_code!$B$2:$B$11,reference_postal_code!$A$2:$A$11)} -> 80231 | P7: South | Q7: OFF-FA-10001883 | R7: Office Supplies | S7: Fasteners | T7: Paper Clip 3974 | U7: 466800 | V7: 4 | W7: 0 | X7: 4668
A8: 7475 | B8: IDN-2014-167199 | C8: 41645 | D8: 41649 | E8: =IF(D8="", C8+3, D8) -> 41649 | F8: Standard Class | G8: KH-9486 | H8: Kairav Hutagalung | I8: Home Office | J8: Indonesia | K8: Denpasar | L8: {=_xlfn.XLOOKUP(M8,reference_province_to_city!$A$2:$A$11,reference_province_to_city!$B$2:$B$11)} -> Denpasar | M8: Bali | N8: 80231 | O8: {=_xlfn.XLOOKUP(M8,reference_postal_code!$B$2:$B$11,reference_postal_code!$A$2:$A$11)} -> 80231 | P8: South | Q8: FUR-CH-10004063 | R8: Furniture | S8: Chairs | T8: Kursi Kantor 0991 | U8: 38607300 | V8: 9 | W8: 0 | X8: 11196117
A9: 7479 | B9: IDN-2014-167199 | C9: 41645 | D9: 41649 | E9: =IF(D9="", C9+3, D9) -> 41649 | F9: Standard Class | G9: KH-9486 | H9: Kairav Hutagalung | I9: Home Office | J9: Indonesia | K9: Denpasar | L9: {=_xlfn.XLOOKUP(M9,reference_province_to_city!$A$2:$A$11,reference_province_to_city!$B$2:$B$11)} -> Denpasar | M9: Bali | N9: 80231 | O9: {=_xlfn.XLOOKUP(M9,reference_postal_code!$B$2:$B$11,reference_postal_code!$A$2:$A$11)} -> 80231 | P9: South | Q9: TEC-PH-10004539 | R9: Technology | S9: Phones | T9: Feature Phone Dual SIM 9424 | U9: 11339400 | V9: 4 | W9: 0 | X9: 3061638
A10: 5328 | B10: IDN-2014-130813 | C10: 41645 | D10: 41647 | E10: =IF(D10="", C10+3, D10) -> 41647 | F10: Second Class | G10: TAMS-6700 | H10: Tgk. Adikara Mardhiyah, S.H. | I10: Consumer | J10: Indonesia | K10: Bandung | L10: {=_xlfn.XLOOKUP(M10,reference_province_to_city!$A$2:$A$11,reference_province_to_city!$B$2:$B$11)} -> Bandung | M10: Jawa Barat | N10: 40111 | O10: {=_xlfn.XLOOKUP(M10,reference_postal_code!$B$2:$B$11,reference_postal_code!$A$2:$A$11)} -> 40111 | P10: West | Q10: OFF-PA-10002005 | R10: Office Supplies | S10: Paper | T10: Kertas HVS A4 0729 | U10: 291600 | V10: 3 | W10: 0 | X10: 139968
A11: 7478 | B11: IDN-2014-167199 | C11: 41645 | D11: 41649 | E11: =IF(D11="", C11+3, D11) -> 41649 | F11: Standard Class | G11: KH-9486 | H11: Kairav Hutagalung | I11: Home Office | J11: Indonesia | K11: Denpasar | L11: {=_xlfn.XLOOKUP(M11,reference_province_to_city!$A$2:$A$11,reference_province_to_city!$B$2:$B$11)} -> Denpasar | M11: Bali | N11: 80231 | O11: {=_xlfn.XLOOKUP(M11,reference_postal_code!$B$2:$B$11,reference_postal_code!$A$2:$A$11)} -> 80231 | P11: South | Q11: TEC-PH-10004977 | R11: Technology | S11: Phones | T11: Feature Phone Dual SIM 2327 | U11: 5879700 | V11: 2 | W11: 0 | X11: 1705113
A12: 7477 | B12: IDN-2014-167199 | C12: 41645 | D12: 41649 | E12: =IF(D12="", C12+3, D12) -> 41649 | F12: Standard Class | G12: KH-9486 | H12: Kairav Hutagalung | I12: Home Office | J12: Indonesia | K12: Denpasar | L12: {=_xlfn.XLOOKUP(M12,reference_province_to_city!$A$2:$A$11,reference_province_to_city!$B$2:$B$11)} -> Denpasar | M12: Bali | N12: 80231 | O12: {=_xlfn.XLOOKUP(M12,reference_postal_code!$B$2:$B$11,reference_postal_code!$A$2:$A$11)} -> 80231 | P12: South | Q12: OFF-AR-10001662 | R12: Office Supplies | S12: Art | T12: Kaligrafi Dinding 2810 | U12: 82200 | V12: 2 | W12: 0 | X12: 22194
A13: 7181 | B13: IDN-2014-106054 | C13: 41645 | D13: 41646 | E13: =IF(D13="", C13+3, D13) -> 41646 | F13: First Class | G13: EP-2984 | H13: Estiawan Prastuti | I13: Corporate | J13: Indonesia | K13: Yogyakarta | L13: {=_xlfn.XLOOKUP(M13,reference_province_to_city!$A$2:$A$11,reference_province_to_city!$B$2:$B$11)} -> Yogyakarta | M13: DI Yogyakarta | N13: 55111 | O13: {=_xlfn.XLOOKUP(M13,reference_postal_code!$B$2:$B$11,reference_postal_code!$A$2:$A$11)} -> 55111 | P13: Central | Q13: OFF-AR-10002399 | R13: Office Supplies | S13: Art | T13: Kaligrafi Dinding 1102 | U13: 191700 | V13: 3 | W13: 0 | X13: 78597
... A19: 594 | B19: IDN-2014-135405 | C19: 41648 | D19: 41652 | E19: =IF(D19="", C19+3, D19) -> 41652 | F19: Standard Class | G19: RP-4156 | H19: Rahmat Pradana | I19: Consumer | J19: Indonesia | K19: Makassar | L19: {=_xlfn.XLOOKUP(M19,reference_province_to_city!$A$2:$A$11,reference_province_to_city!$B$2:$B$11)} -> Makassar | M19: Sulawesi Selatan | N19: 90111 | O19: {=_xlfn.XLOOKUP(M19,reference_postal_code!$B$2:$B$11,reference_postal_code!$A$2:$A$11)} -> 90111 | P19: South | Q19: TEC-AC-10001266 | R19: Technology | S19: Accessories | T19: Headset 3811 | U19: 468000 | V19: 3 | W19: 0.2 | X19: 146250
A20: 867 | B20: IDN-2014-149020 | C20: 41649 | D20: 41654 | E20: =IF(D20="", C20+3, D20) -> 41654 | F20: Standard Class | G20: WM-4177 | H20: Wulan Mardhiyah | I20: Corporate | J20: Indonesia | L20: {=_xlfn.XLOOKUP(M20,reference_province_to_city!$A$2:$A$11,reference_province_to_city!$B$2:$B$11)} -> Bandung | M20: Jawa Barat | N20: 40111 | O20: {=_xlfn.XLOOKUP(M20,reference_postal_code!$B$2:$B$11,reference_postal_code!$A$2:$A$11)} -> 40111 | P20: West | Q20: FUR-FU-10000965 | R20: Furniture | S20: Furnishings | T20: Lampu Meja 7242 | U20: 779100 | V20: 1 | W20: 0 | X20: 319431
A21: 866 | B21: IDN-2014-149020 | C21: 41649 | E21: =IF(D21="", C21+3, D21) -> 41652 | F21: Standard Class | G21: WM-4177 | H21: Wulan Mardhiyah | I21: Corporate | J21: Indonesia | K21: Bandung | L21: {=_xlfn.XLOOKUP(M21,reference_province_to_city!$A$2:$A$11,reference_province_to_city!$B$2:$B$11)} -> Bandung | M21: Jawa Barat | N21: 40111 | O21: {=_xlfn.XLOOKUP(M21,reference_postal_code!$B$2:$B$11,reference_postal_code!$A$2:$A$11)} -> 40111 | P21: West | Q21: OFF-LA-10004272 | R21: Office Supplies | S21: Labels | T21: Label Stiker 5752 | U21: 43350 | V21: 1 | W21: 0 | X21: 20374
A22: 717 | B22: IDN-2014-130092 | C22: 41650 | D22: 41653 | E22: =IF(D22="", C22+3, D22) -> 41653 | F22: First Class | G22: AH-8588 | H22: Azalea Haryanto | I22: Consumer | J22: Indonesia | K22: Denpasar | L22: {=_xlfn.XLOOKUP(M22,reference_province_to_city!$A$2:$A$11,reference_province_to_city!$B$2:$B$11)} -> Denpasar | M22: Bali | N22: 80231 | O22: {=_xlfn.XLOOKUP(M22,reference_postal_code!$B$2:$B$11,reference_postal_code!$A$2:$A$11)} -> 80231 | P22: South | Q22: FUR-FU-10000010 | R22: Furniture | S22: Furnishings | T22: Karpet Kantor 9473 | U22: 149100 | V22: 2 | W22: 0 | X22: 46221
A23: 9629 | B23: IDN-2014-118192 | C23: 41652 | D23: 41657 | E23: =IF(D23="", C23+3, D23) -> 41657 | F23: Standard Class | G23: HPJ-5188 | H23: Hj. Puti Jailani | I23: Consumer | J23: Indonesia | K23: Surabaya | L23: {=_xlfn.XLOOKUP(M23,reference_province_to_city!$A$2:$A$11,reference_province_to_city!$B$2:$B$11)} -> Surabaya | M23: Jawa Timur | N23: 60231 | O23: {=_xlfn.XLOOKUP(M23,reference_postal_code!$B$2:$B$11,reference_postal_code!$A$2:$A$11)} -> 60231 | P23: East | Q23: OFF-PA-10002947 | R23: Office Supplies | S23: Paper | T23: Kertas Foto 9455 | U23: 561120 | V23: 7 | W23: 0.2 | X23: 196392
A24: 765 | B24: IDN-2014-162775 | C24: 41652 | D24: 41654 | E24: =IF(D24="", C24+3, D24) -> 41654 | F24: Second Class | G24: JW-2895 | H24: Jaswadi Wahyudin | I24: Corporate | J24: Indonesia | K24: Makassar | L24: {=_xlfn.XLOOKUP(M24,reference_province_to_city!$A$2:$A$11,reference_province_to_city!$B$2:$B$11)} -> Makassar | M24: Sulawesi Selatan | N24: 90111 | O24: {=_xlfn.XLOOKUP(M24,reference_postal_code!$B$2:$B$11,reference_postal_code!$A$2:$A$11)} -> 90111 | P24: South | Q24: OFF-EN-10001532 | R24: Office Supplies | S24: Envelopes | T24: Amplop Putih 9241 | U24: 764100 | V24: 3 | W24: 0 | X24: 382050
A25: 9630 | B25: IDN-2014-118192 | C25: 41652 | E25: =IF(D25="", C25+3, D25) -> 41655 | F25: Standard Class | G25: HPJ-5188 | H25: Hj. Puti Jailani | I25: Consumer | J25: Indonesia | K25: Surabaya | L25: {=_xlfn.XLOOKUP(M25,reference_province_to_city!$A$2:$A$11,reference_province_to_city!$B$2:$B$11)} -> Surabaya | M25: Jawa Timur | N25: 60231 | O25: {=_xlfn.XLOOKUP(M25,reference_postal_code!$B$2:$B$11,reference_postal_code!$A$2:$A$11)} -> 60231 | P25: East | Q25: OFF-BI-10003476 | R25: Office Supplies | S25: Binders | T25: Binder Kancing A4 8011 | U25: 51570 | V25: 2 | W25: 0.7 | X25: -37818
A26: 4940 | B26: IDN-2014-157147 | C26: 41652 | D26: 41657 | E26: =IF(D26="", C26+3, D26) -> 41657 | F26: Standard Class | G26: YG-2912 | H26: Yessi Gunawan | I26: Consumer | J26: Indonesia | K26: Yogyakarta | L26: {=_xlfn.XLOOKUP(M26,reference_province_to_city!$A$2:$A$11,reference_province_to_city!$B$2:$B$11)} -> Yogyakarta | M26: DI Yogyakarta | N26: 55111 | O26: {=_xlfn.XLOOKUP(M26,reference_postal_code!$B$2:$B$11,reference_postal_code!$A$2:$A$11)} -> 55111 | P26: Central | Q26: OFF-AR-10003514 | R26: Office Supplies | S26: Art | T26: Poster Ilustrasi 5747 | U26: 298500 | V26: 5 | W26: 0 | X26: 98505
A27: 4939 | B27: IDN-2014-157147 | C27: 41652 | D27: 41657 | E27: =IF(D27="", C27+3, D27) -> 41657 | F27: Standard Class | G27: YG-2912 | H27: Yessi Gunawan | I27: Consumer | J27: Indonesia | K27: Yogyakarta | L27: {=_xlfn.XLOOKUP(M27,reference_province_to_city!$A$2:$A$11,reference_province_to_city!$B$2:$B$11)} -> Yogyakarta | M27: DI Yogyakarta | N27: 55111 | O27: {=_xlfn.XLOOKUP(M27,reference_postal_code!$B$2:$B$11,reference_postal_code!$A$2:$A$11)} -> 55111 | P27: Central | Q27: FUR-BO-10003034 | R27: Furniture | S27: Bookcases | T27: Rak Buku Kayu 8148 | U27: 5009985 | V27: 3 | W27: 0.15 | X27: 58941
A28: 768 | B28: IDN-2014-162775 | C28: 41652 | D28: 41654 | E28: =IF(D28="", C28+3, D28) -> 41654 | F28: Second Class | G28: JW-2895 | H28: Jaswadi Wahyudin | I28: Corporate | J28: Indonesia | K28: Makassar | L28: {=_xlfn.XLOOKUP(M28,reference_province_to_city!$A$2:$A$11,reference_province_to_city!$B$2:$B$11)} -> Makassar | M28: Sulawesi Selatan | N28: 90111 | O28: {=_xlfn.XLOOKUP(M28,reference_postal_code!$B$2:$B$11,reference_postal_code!$A$2:$A$11)} -> 90111 | P28: South | Q28: OFF-ST-10000025 | R28: Office Supplies | S28: Storage | T28: Rak Dokumen 5610 | U28: 8588700 | V28: 6 | W28: 0 | X28: 515322
A29: 2979 | B29: IDN-2014-109232 | C29: 41652 | D29: 41655 | E29: =IF(D29="", C29+3, D29) -> 41655 | F29: Second Class | G29: MB-8431 | H29: Mursita Budiyanto | I29: Consumer | J29: Indonesia | K29: Makassar | L29: {=_xlfn.XLOOKUP(M29,reference_province_to_city!$A$2:$A$11,reference_province_to_city!$B$2:$B$11)} -> Makassar | M29: Sulawesi Selatan | N29: 90111 | O29: {=_xlfn.XLOOKUP(M29,reference_postal_code!$B$2:$B$11,reference_postal_code!$A$2:$A$11)} -> 90111 | P29: South | Q29: FUR-CH-10000422 | R29: Furniture | S29: Chairs | T29: Kursi Lipat 8795 | U29: 8189100 | V29: 6 | W29: 0 | X29: 1310256
A30: 764 | B30: IDN-2014-162775 | C30: 41652 | D30: 41654 | E30: =IF(D30="", C30+3, D30) -> 41654 | F30: Second Class | G30: JW-2895 | H30: Jaswadi Wahyudin | I30: Corporate | J30: Indonesia | K30: Makassar | L30: {=_xlfn.XLOOKUP(M30,reference_province_to_city!$A$2:$A$11,reference_province_to_city!$B$2:$B$11)} -> Makassar | M30: Sulawesi Selatan | N30: 90111 | O30: {=_xlfn.XLOOKUP(M30,reference_postal_code!$B$2:$B$11,reference_postal_code!$A$2:$A$11)} -> 90111 | P30: South | Q30: OFF-EN-10001990 | R30: Office Supplies | S30: Envelopes | T30: Amplop Coklat 2012 | U30: 170400 | V30: 2 | W30: 0 | X30: 80088
A31: 4938 | B31: IDN-2014-157147 | C31: 41652 | D31: 41657 | E31: =IF(D31="", C31+3, D31) -> 41657 | F31: Standard Class | G31: YG-2912 | H31: Yessi Gunawan | I31: Consumer | J31: Indonesia | K31: Yogyakarta | L31: {=_xlfn.XLOOKUP(M31,reference_province_to_city!$A$2:$A$11,reference_province_to_city!$B$2:$B$11)} -> Yogyakarta | M31: DI Yogyakarta | N31: 55111 | O31: {=_xlfn.XLOOKUP(M31,reference_postal_code!$B$2:$B$11,reference_postal_code!$A$2:$A$11)} -> 55111 | P31: Central | Q31: OFF-ST-10000078 | R31: Office Supplies | S31: Storage | T31: Rak Dokumen 9769 | U31: 19887750 | V31: 5 | W31: 0 | X31: 3579795
A32: 767 | B32: IDN-2014-162775 | C32: 41652 | D32: 41654 | E32: =IF(D32="", C32+3, D32) -> 41654 | F32: Second Class | G32: JW-2895 | H32: Jaswadi Wahyudin | I32: Corporate | J32: Indonesia | K32: Makassar | L32: {=_xlfn.XLOOKUP(M32,reference_province_to_city!$A$2:$A$11,reference_province_to_city!$B$2:$B$11)} -> Makassar | M32: Sulawesi Selatan | N32: 90111 | O32: {=_xlfn.XLOOKUP(M32,reference_postal_code!$B$2:$B$11,reference_postal_code!$A$2:$A$11)} -> 90111 | P32: South | Q32: OFF-BI-10004187 | R32: Office Supplies | S32: Binders | T32: Binder Plastik A4 5908 | U32: 84600 | V32: 3 | W32: 0 | X32: 40608
A33: 766 | B33: IDN-2014-162775 | C33: 41652 | D33: 41654 | E33: =IF(D33="", C33+3, D33) -> 41654 | F33: Second Class | G33: JW-2895 | H33: Jaswadi Wahyudin | I33: Corporate | J33: Indonesia | K33: Makassar | L33: {=_xlfn.XLOOKUP(M33,reference_province_to_city!$A$2:$A$11,reference_province_to_city!$B$2:$B$11)} -> Makassar | M33: Sulawesi Selatan | N33: 90111 | O33: {=_xlfn.XLOOKUP(M33,reference_postal_code!$B$2:$B$11,reference_postal_code!$A$2:$A$11)} -> 90111 | P33: South | Q33: TEC-AC-10003174 | R33: Technology | S33: Accessories | T33: Headset 0423 | U33: 9701100 | V33: 6 | W33: 0 | X33: 3880440
A34: 6475 | B34: IDN-2014-149524 | C34: 41653 | D34: 41654 | E34: =IF(D34="", C34+3, D34) -> 41654 | F34: First Class | G34: SKPS-6667 | H34: Sutan Kasusra Prayoga, S.IP | I34: Corporate | J34: Indonesia | K34: Palembang | L34: {=_xlfn.XLOOKUP(M34,reference_province_to_city!$A$2:$A$11,reference_province_to_city!$B$2:$B$11)} -> Palembang | M34: Sumatera Selatan | N34: 30111 | O34: {=_xlfn.XLOOKUP(M34,reference_postal_code!$B$2:$B$11,reference_postal_code!$A$2:$A$11)} -> 30111 | P34: Central | Q34: FUR-BO-10003433 | R34: Furniture | S34: Bookcases | T34: Rak Buku Besi 9995 | U34: 929400 | V34: 4 | W34: 0.5 | X34: -799284
A35: 1914 | B35: IDN-2014-103366 | C35: 41654 | D35: 41656 | E35: =IF(D35="", C35+3, D35) -> 41656 | F35: First Class | G35: DSM-1764 | H35: Dewi Salahudin, M.Pd | I35: Consumer | J35: Indonesia | K35: Surabaya | L35: {=_xlfn.XLOOKUP(M35,reference_province_to_city!$A$2:$A$11,reference_province_to_city!$B$2:$B$11)} -> Surabaya | M35: Jawa Timur | N35: 60231 | O35: {=_xlfn.XLOOKUP(M35,reference_postal_code!$B$2:$B$11,reference_postal_code!$A$2:$A$11)} -> 60231 | P35: East | Q35: TEC-AC-10003628 | R35: Technology | S35: Accessories | T35: Flashdisk 4202 | U35: 2249250 | V35: 5 | W35: 0 | X35: 989670
A36: 971 | B36: IDN-2014-115791 | C36: 41655 | D36: 41657 | E36: =IF(D36="", C36+3, D36) -> 41657 | F36: Second Class | G36: SH-2227 | H36: Sarah Haryanti | I36: Consumer | J36: Indonesia | K36: Bandung | L36: {=_xlfn.XLOOKUP(M36,reference_province_to_city!$A$2:$A$11,reference_province_to_city!$B$2:$B$11)} -> Bandung | M36: Jawa Barat | N36: 40111 | O36: {=_xlfn.XLOOKUP(M36,reference_postal_code!$B$2:$B$11,reference_postal_code!$A$2:$A$11)} -> 40111 | P36: West | Q36: FUR-FU-10001095 | R36: Furniture | S36: Furnishings | T36: Lampu Meja 5088 | U36: 1906560 | V36: 6 | W36: 0.2 | X36: 428976
A37: 972 | B37: IDN-2014-115791 | C37: 41655 | D37: 41657 | E37: =IF(D37="", C37+3, D37) -> 41657 | F37: Second Class | G37: SH-2227 | H37: Sarah Haryanti | I37: Consumer | J37: Indonesia | K37: Bandung | L37: {=_xlfn.XLOOKUP(M37,reference_province_to_city!$A$2:$A$11,reference_province_to_city!$B$2:$B$11)} -> Bandung | M37: Jawa Barat | N37: 40111 | O37: {=_xlfn.XLOOKUP(M37,reference_postal_code!$B$2:$B$11,reference_postal_code!$A$2:$A$11)} -> 40111 | P37: West | Q37: TEC-PH-10004614 | R37: Technology | S37: Phones | T37: Smartphone Android 9250 | U37: 1863000 | V37: 3 | W37: 0.4 | X37: -465750
... A60: 6332 | B60: IDN-2014-167927 | C60: 41659 | D60: 41665 | E60: =IF(D60="", C60+3, D60) -> 41665 | F60: Standard Class | G60: FTS-1955 | H60: Fitriani Tamba, S.Kom | I60: Consumer | J60: Indonesia | K60: Jakarta | L60: {=_xlfn.XLOOKUP(M60,reference_province_to_city!$A$2:$A$11,reference_province_to_city!$B$2:$B$11)} -> Jakarta | M60: DKI Jakarta | N60: 10110 | O60: {=_xlfn.XLOOKUP(M60,reference_postal_code!$B$2:$B$11,reference_postal_code!$A$2:$A$11)} -> 10110 | P60: West | Q60: OFF-AR-10004456 | R60: Office Supplies | S60: Art | T60: Lukisan Cat Air 0913 | U60: 658800 | V60: 3 | W60: 0 | X60: 191052
A61: 1123 | B61: IDN-2014-147627 | C61: 41659 | D61: 41665 | E61: =IF(D61="", C61+3, D61) -> 41665 | F61: Standard Class | G61: DDSS-4488 | H61: drg. Dartono Suryatmi, S.Pt | I61: Consumer | J61: Indonesia | L61: {=_xlfn.XLOOKUP(M61,reference_province_to_city!$A$2:$A$11,reference_province_to_city!$B$2:$B$11)} -> Surabaya | M61: Jawa Timur | N61: 60231 | O61: {=_xlfn.XLOOKUP(M61,reference_postal_code!$B$2:$B$11,reference_postal_code!$A$2:$A$11)} -> 60231 | P61: East | Q61: OFF-AR-10002375 | R61: Office Supplies | S61: Art | T61: Kaligrafi Dinding 6594 | U61: 344400 | V61: 7 | W61: 0 | X61: 99876
A62: 9990 | B62: IDN-2014-110422 | C62: 41660 | D62: 41662 | E62: =IF(D62="", C62+3, D62) -> 41662 | F62: Second Class | G62: DSMS-5102 | H62: Dr. Salsabila Maryati, S.T. | I62: Consumer | J62: Indonesia | K62: medan | L62: {=_xlfn.XLOOKUP(M62,reference_province_to_city!$A$2:$A$11,reference_province_to_city!$B$2:$B$11)} -> Medan | M62: Sumatera Utara | N62: 20111 | O62: {=_xlfn.XLOOKUP(M62,reference_postal_code!$B$2:$B$11,reference_postal_code!$A$2:$A$11)} -> 20111 | P62: Central | Q62: FUR-FU-10001889 | R62: Furniture | S62: Furnishings | T62: Karpet Kantor 8703 | U62: 378720 | V62: 3 | W62: 0.2 | X62: 61542
A63: 9887 | B63: IDN-2014-146997 | C63: 41662 | D63: 41666 | E63: =IF(D63="", C63+3, D63) -> 41666 | F63: Standard Class | G63: JP-2861 | H63: Jessica Pudjiastuti | I63: Consumer | J63: Indonesia | K63: Bandung | L63: {=_xlfn.XLOOKUP(M63,reference_province_to_city!$A$2:$A$11,reference_province_to_city!$B$2:$B$11)} -> Bandung | M63: Jawa Barat | N63: 40111 | O63: {=_xlfn.XLOOKUP(M63,reference_postal_code!$B$2:$B$11,reference_postal_code!$A$2:$A$11)} -> 40111 | P63: West | Q63: OFF-FA-10003467 | R63: Office Supplies | S63: Fasteners | T63: Penjepit Kertas 9955 | U63: 89100 | V63: 3 | W63: 0 | X63: 0
A64: 9156 | B64: IDN-2014-102645 | C64: 41662 | D64: 41667 | E64: =IF(D64="", C64+3, D64) -> 41667 | F64: Standard Class | G64: NP-2969 | H64: Najib Pratama | I64: Consumer | J64: Indonesia | K64: Jakarta | L64: {=_xlfn.XLOOKUP(M64,reference_province_to_city!$A$2:$A$11,reference_province_to_city!$B$2:$B$11)} -> Jakarta | M64: DKI Jakarta | N64: 10110 | O64: {=_xlfn.XLOOKUP(M64,reference_postal_code!$B$2:$B$11,reference_postal_code!$A$2:$A$11)} -> 10110 | P64: West | Q64: OFF-PA-10001804 | R64: Office Supplies | S64: Paper | T64: Kertas Foto 6592 | U64: 601200 | V64: 6 | W64: 0 | X64: 288576
A65: 2583 | B65: IDN-2014-155502 | C65: 41665 | D65: 41670 | E65: =IF(D65="", C65+3, D65) -> 41670 | F65: Standard Class | G65: HP-4183 | H65: Harto Purwanti | I65: Home Office | J65: Indonesia | L65: {=_xlfn.XLOOKUP(M65,reference_province_to_city!$A$2:$A$11,reference_province_to_city!$B$2:$B$11)} -> Makassar | M65: Sulawesi Selatan | O65: {=_xlfn.XLOOKUP(M65,reference_postal_code!$B$2:$B$11,reference_postal_code!$A$2:$A$11)} -> 90111 | P65: South | Q65: TEC-PH-10004833 | R65: Technology | S65: Phones | T65: Feature Phone Dual SIM 3552 | U65: 2330250 | V65: 13 | W65: 0 | X65: 0
A66: 8151 | B66: IDN-2014-167997 | C66: 41665 | D66: 41668 | E66: =IF(D66="", C66+3, D66) -> 41668 | F66: First Class | G66: DY-7007 | H66: Darman Yuliarti | I66: Corporate | J66: Indonesia | K66: Surabaya | L66: {=_xlfn.XLOOKUP(M66,reference_province_to_city!$A$2:$A$11,reference_province_to_city!$B$2:$B$11)} -> Surabaya | M66: Jawa Timur | N66: 60231 | O66: {=_xlfn.XLOOKUP(M66,reference_postal_code!$B$2:$B$11,reference_postal_code!$A$2:$A$11)} -> 60231 | P66: East | Q66: FUR-BO-10004409 | R66: Furniture | S66: Bookcases | T66: Rak Buku Besi 9929 | U66: 2129400 | V66: 2 | W66: 0 | X66: 596232
A67: 2581 | B67: IDN-2014-155502 | C67: 41665 | D67: 41670 | E67: =IF(D67="", C67+3, D67) -> 41670 | F67: Standard Class | G67: HP-4183 | H67: Harto Purwanti | I67: Home Office | J67: Indonesia | K67: Makassar | L67: {=_xlfn.XLOOKUP(M67,reference_province_to_city!$A$2:$A$11,reference_province_to_city!$B$2:$B$11)} -> Makassar | M67: Sulawesi Selatan | N67: 90111 | O67: {=_xlfn.XLOOKUP(M67,reference_postal_code!$B$2:$B$11,reference_postal_code!$A$2:$A$11)} -> 90111 | P67: South | Q67: OFF-PA-10003072 | R67: Office Supplies | S67: Paper | T67: Kertas HVS A4 1914 | U67: 291600 | V67: 3 | W67: 0 | X67: 139968
...

Sheet reference_province_to_city
A1: provinsi | B1: kota
A2: DKI Jakarta | B2: Jakarta
A3: Jawa Barat | B3: Bandung
A4: Jawa Tengah | B4: Semarang
A5: DI Yogyakarta | B5: Yogyakarta
A6: Jawa Timur | B6: Surabaya
A7: Bali | B7: Denpasar
A8: Sumatera Utara | B8: Medan
A9: Sumatera Selatan | B9: Palembang
A10: Kalimantan Timur | B10: Balikpapan
A11: Sulawesi Selatan | B11: Makassar

Sheet reference_postal_code
A1: kode_pos | B1: provinsi
A2: 10110 | B2: DKI Jakarta
A3: 20111 | B3: Sumatera Utara
A4: 30111 | B4: Sumatera Selatan
A5: 40111 | B5: Jawa Barat
A6: 50111 | B6: Jawa Tengah
A7: 55111 | B7: DI Yogyakarta
A8: 60231 | B8: Jawa Timur
A9: 76114 | B9: Kalimantan Timur
A10: 80231 | B10: Bali
A11: 90111 | B11: Sulawesi Selatan

Sheet basic_analysis
A1: Pertanyaan | B1: Jawaban
A2: Berapa total pendapatan (bukan keuntungan) yang didapatkan sepanjang tahun 2016? | B2: =SUMIFS( sources!U2:U10077, sources!C2:C10077, ">="&DATE(2016,1,1), sources!C2:C10077, "<"&DATE(2017,1,1) ) -> 9246372270
A3: Berapa total kuantitas produk yang terjual sepanjang tahun 2016? | B3: =SUMIFS( sources!V2:V10077, sources!C2:C10077, ">="&DATE(2016,1,1), sources!C2:C10077, "<="&DATE(2016,12,31) ) -> 9936
A4: Berapa jumlah pemesanan dengan metode pengiriman "First Class" pada periode 2014–2017? | B4: =COUNTIFS( sources!F2:F10077,"First Class", sources!C2:C10077,">="&DATE(2014,1,1), sources!C2:C10077,"<"&DATE(2017,12,31) ) -> 1548
A5: HINT
A7: Total pendapatan sepanjang tahun 2016 bernilai bilangan positif dan berada pada kisaran Rp9,2 miliar hingga Rp9,3 miliar.
A10: Total jumlah produk yang terjual pada tahun 2016 bernilai bilangan positif dan berada pada rentang 9900 hingga 10000 unit.
A13: Jumlah pemesanan dengan metode pengiriman "First Class" pada periode 2014 hingga 2017 bernilai positif dan berada pada kisaran 1.500 hingga 1.600 pesanan.

Sheet query_analysis
A1: Pertanyaan | B1: Jawaban
A2: Berapa jumlah pelanggan di setiap kota? (Tampilkan data jumlah pelanggan di setiap kota) | B2: =IFERROR(__xludf.DUMMYFUNCTION("QUERY(sources!A1:X10077, ""SELECT L, COUNT(H) GROUP BY L ORDER BY COUNT(H) DESC"", 1)"),"clean_kota") -> clean_kota | C2: =IFERROR(__xludf.DUMMYFUNCTION("""COMPUTED_VALUE"""),"count nama_pelanggan") -> count nama_pelanggan
B3: =IFERROR(__xludf.DUMMYFUNCTION("""COMPUTED_VALUE"""),"Makassar") -> Makassar | C3: =IFERROR(__xludf.DUMMYFUNCTION("""COMPUTED_VALUE"""),1103.0) -> 1103
B4: =IFERROR(__xludf.DUMMYFUNCTION("""COMPUTED_VALUE"""),"Surabaya") -> Surabaya | C4: =IFERROR(__xludf.DUMMYFUNCTION("""COMPUTED_VALUE"""),1101.0) -> 1101
B5: =IFERROR(__xludf.DUMMYFUNCTION("""COMPUTED_VALUE"""),"Denpasar") -> Denpasar | C5: =IFERROR(__xludf.DUMMYFUNCTION("""COMPUTED_VALUE"""),1069.0) -> 1069
B6: =IFERROR(__xludf.DUMMYFUNCTION("""COMPUTED_VALUE"""),"Semarang") -> Semarang | C6: =IFERROR(__xludf.DUMMYFUNCTION("""COMPUTED_VALUE"""),1010.0) -> 1010
B7: =IFERROR(__xludf.DUMMYFUNCTION("""COMPUTED_VALUE"""),"Balikpapan") -> Balikpapan | C7: =IFERROR(__xludf.DUMMYFUNCTION("""COMPUTED_VALUE"""),998.0) -> 998
B8: =IFERROR(__xludf.DUMMYFUNCTION("""COMPUTED_VALUE"""),"Jakarta") -> Jakarta | C8: =IFERROR(__xludf.DUMMYFUNCTION("""COMPUTED_VALUE"""),994.0) -> 994
B9: =IFERROR(__xludf.DUMMYFUNCTION("""COMPUTED_VALUE"""),"Yogyakarta") -> Yogyakarta | C9: =IFERROR(__xludf.DUMMYFUNCTION("""COMPUTED_VALUE"""),983.0) -> 983
B10: =IFERROR(__xludf.DUMMYFUNCTION("""COMPUTED_VALUE"""),"Medan") -> Medan | C10: =IFERROR(__xludf.DUMMYFUNCTION("""COMPUTED_VALUE"""),946.0) -> 946
B11: =IFERROR(__xludf.DUMMYFUNCTION("""COMPUTED_VALUE"""),"Bandung") -> Bandung | C11: =IFERROR(__xludf.DUMMYFUNCTION("""COMPUTED_VALUE"""),940.0) -> 940
B12: =IFERROR(__xludf.DUMMYFUNCTION("""COMPUTED_VALUE"""),"Palembang") -> Palembang | C12: =IFERROR(__xludf.DUMMYFUNCTION("""COMPUTED_VALUE"""),932.0) -> 932
A15: Berapa rata-rata penjualan di setiap kota sepanjang tahun 2014-2017? (Tampilkan data rata-rata penjualan setiap kota) | B15: =IFERROR(__xludf.DUMMYFUNCTION("QUERY(sources!A1:X10077, ""SELECT L, AVG(U) GROUP BY L ORDER BY AVG(U) DESC"", 1)"),"clean_kota") -> clean_kota | C15: =IFERROR(__xludf.DUMMYFUNCTION("""COMPUTED_VALUE"""),"avg penjualan") -> avg penjualan
B16: =IFERROR(__xludf.DUMMYFUNCTION("""COMPUTED_VALUE"""),"Balikpapan") -> Balikpapan | C16: =IFERROR(__xludf.DUMMYFUNCTION("""COMPUTED_VALUE"""),4085450.875751503) -> 4085450.9
B17: =IFERROR(__xludf.DUMMYFUNCTION("""COMPUTED_VALUE"""),"Medan") -> Medan | C17: =IFERROR(__xludf.DUMMYFUNCTION("""COMPUTED_VALUE"""),3700440.084566596) -> 3700440.1
B18: =IFERROR(__xludf.DUMMYFUNCTION("""COMPUTED_VALUE"""),"Jakarta") -> Jakarta | C18: =IFERROR(__xludf.DUMMYFUNCTION("""COMPUTED_VALUE"""),3675763.5331991953) -> 3675763.5
B19: =IFERROR(__xludf.DUMMYFUNCTION("""COMPUTED_VALUE"""),"Denpasar") -> Denpasar | C19: =IFERROR(__xludf.DUMMYFUNCTION("""COMPUTED_VALUE"""),3538502.689429373) -> 3538502.7
B20: =IFERROR(__xludf.DUMMYFUNCTION("""COMPUTED_VALUE"""),"Surabaya") -> Surabaya | C20: =IFERROR(__xludf.DUMMYFUNCTION("""COMPUTED_VALUE"""),3385368.8147138963) -> 3385368.8
B21: =IFERROR(__xludf.DUMMYFUNCTION("""COMPUTED_VALUE"""),"Semarang") -> Semarang | C21: =IFERROR(__xludf.DUMMYFUNCTION("""COMPUTED_VALUE"""),3365852.07029703) -> 3365852.1
B22: =IFERROR(__xludf.DUMMYFUNCTION("""COMPUTED_VALUE"""),"Yogyakarta") -> Yogyakarta | C22: =IFERROR(__xludf.DUMMYFUNCTION("""COMPUTED_VALUE"""),3345146.392675483) -> 3345146.4
B23: =IFERROR(__xludf.DUMMYFUNCTION("""COMPUTED_VALUE"""),"Makassar") -> Makassar | C23: =IFERROR(__xludf.DUMMYFUNCTION("""COMPUTED_VALUE"""),3272766.6183136897) -> 3272766.6
B24: =IFERROR(__xludf.DUMMYFUNCTION("""COMPUTED_VALUE"""),"Palembang") -> Palembang | C24: =IFERROR(__xludf.DUMMYFUNCTION("""COMPUTED_VALUE"""),3088697.4978540773) -> 3088697.5
B25: =IFERROR(__xludf.DUMMYFUNCTION("""COMPUTED_VALUE"""),"Bandung") -> Bandung | C25: =IFERROR(__xludf.DUMMYFUNCTION("""COMPUTED_VALUE"""),2937980.2521276595) -> 2937980.3
A26: Berapa total transaksi yang terjadi pada setiap harinya? (Tampilkan data dari senin sampai minggu) | B26: =IFERROR(__xludf.DUMMYFUNCTION("ARRAYFORMULA(QUERY({TEXT(sources!C1:C10077, ""dddd""), sources!A1:X10077}, ""SELECT Col1, COUNT(Col3) GROUP BY Col1 LABEL Col1 'Hari', COUNT(Col3) 'Total Transaksi'"", 1)) "),"Hari") -> Hari | C26: =IFERROR(__xludf.DUMMYFUNCTION("""COMPUTED_VALUE"""),"Total Transaksi") -> Total Transaksi
B27: =IFERROR(__xludf.DUMMYFUNCTION("""COMPUTED_VALUE"""),"Friday") -> Friday | C27: =IFERROR(__xludf.DUMMYFUNCTION("""COMPUTED_VALUE"""),1836.0) -> 1836
B28: =IFERROR(__xludf.DUMMYFUNCTION("""COMPUTED_VALUE"""),"Monday") -> Monday | C28: =IFERROR(__xludf.DUMMYFUNCTION("""COMPUTED_VALUE"""),1887.0) -> 1887
B29: =IFERROR(__xludf.DUMMYFUNCTION("""COMPUTED_VALUE"""),"Saturday") -> Saturday | C29: =IFERROR(__xludf.DUMMYFUNCTION("""COMPUTED_VALUE"""),1668.0) -> 1668
B30: =IFERROR(__xludf.DUMMYFUNCTION("""COMPUTED_VALUE"""),"Sunday") -> Sunday | C30: =IFERROR(__xludf.DUMMYFUNCTION("""COMPUTED_VALUE"""),1724.0) -> 1724
B31: =IFERROR(__xludf.DUMMYFUNCTION("""COMPUTED_VALUE"""),"Thursday") -> Thursday | C31: =IFERROR(__xludf.DUMMYFUNCTION("""COMPUTED_VALUE"""),1473.0) -> 1473
B32: =IFERROR(__xludf.DUMMYFUNCTION("""COMPUTED_VALUE"""),"Tuesday") -> Tuesday | C32: =IFERROR(__xludf.DUMMYFUNCTION("""COMPUTED_VALUE"""),1114.0) -> 1114
B33: =IFERROR(__xludf.DUMMYFUNCTION("""COMPUTED_VALUE"""),"Wednesday") -> Wednesday | C33: =IFERROR(__xludf.DUMMYFUNCTION("""COMPUTED_VALUE"""),374.0) -> 374
A34: HINT
A36: Kota dengan jumlah pelanggan terbanyak adalah Makassar, diikuti oleh Surabaya dan Denpasar.
A38: Rata-rata penjualan tertinggi terdapat di Kota Balikpapan, yaitu sekitar Rp4.000.000 atau lebih.
A41: Hari dengan jumlah transaksi terbanyak adalah Senin, dengan sekitar 1.800 transaksi atau lebih.

Sheet top_lima_produk
A1: Pertanyaan | B1: Jawaban
A2: Lima produk yang memiliki penjualan tertinggi sepanjang tahun (2014-2017)
A8: HINT
A10: Lima produk dengan nilai tertinggi adalah Mesin Fotokopi xxx, Ordner Arsip xxx, Mesin Laminating xxx, Binder Kancing xxx, dan Binder Plastik xxx. Mesin fotokopi tersebut berada pada kisaran harga Rp700.000.000.
